<?xml version="1.0" ?>

<robot name="mm" xmlns:xacro="http://www.ros.org/wiki/xacro">
  <!--#################### UR5 ##########################################################################-->
   <gazebo>
    <plugin name="ros_control" filename="libgazebo_ros_control.so">
      <robotNamespace>/</robotNamespace>
      <robotSimType>gazebo_ros_control/DefaultRobotHWSim</robotSimType>
      <legacyModeNS>true</legacyModeNS>

    </plugin>

  </gazebo>
<property name="PI" value="3.1415926" />
  <material name="black">
    <color rgba="0.0 0.0 0.0 1.0"/>FF
  </material>
  <material name="blue">
    <color rgba="0.0 0.0 0.8 1.0"/>
  </material>
  <material name="green">
    <color rgba="0.0 0.8 0.0 1.0"/>
  </material>
  <material name="grey">
    <color rgba="0.2 0.2 0.2 1.0"/>
  </material>
  <material name="orange">
    <color rgba="1.0 0.423529411765 0.0392156862745 1.0"/>
  </material>
  <material name="brown">
    <color rgba="0.870588235294 0.811764705882 0.764705882353 1.0"/>
  </material>
  <material name="red">
    <color rgba="0.8 0.0 0.0 1.0"/>
  </material>
  <material name="white">
    <color rgba="1.0 1.0 1.0 1.0"/>
  </material>
  <!-- gripper -->
  <!-- arm -->
  <link name="arm_base_link">
    <visual>
      <geometry>
        <mesh filename="package://mm_description/meshes/ur5/visual/base.dae"/>
      </geometry>
      <material name="LightGrey">
        <color rgba="0.7 0.7 0.7 1.0"/>
      </material>
    </visual>
    <collision>
      <geometry>
        <mesh filename="package://mm_description/meshes/ur5/collision/base.stl"/>
      </geometry>
    </collision>
    <inertial>
      <mass value="4.0"/>
      <origin rpy="0 0 0" xyz="0.0 0.0 0.0"/>
      <inertia ixx="0.00443333156" ixy="0.0" ixz="0.0" iyy="0.00443333156" iyz="0.0" izz="0.0072"/>
    </inertial>
  </link>

  <joint name="arm_shoulder_pan_joint" type="revolute">
    <parent link="arm_base_link"/>
    <child link="arm_shoulder_link"/>
    <origin rpy="0.0 0.0 0.0" xyz="0.0 0.0 0.08"/>
    <axis xyz="0 0 1"/>
    <limit effort="150.0" lower="-3.14159" upper="3.14159" velocity="3.15"/>
    <dynamics damping="0.0" friction="0.0"/>
  </joint>

  <link name="arm_shoulder_link">
    <visual>
      <geometry>
        <mesh filename="package://mm_description/meshes/ur5/visual/shoulder.dae"/>
      </geometry>
      <material name="LightGrey">
        <color rgba="0.7 0.7 0.7 1.0"/>
      </material>
    </visual>
    <collision>
      <geometry>
        <mesh filename="package://mm_description/meshes/ur5/collision/shoulder.stl"/>
      </geometry>
    </collision>
    <inertial>
      <mass value="3.7"/>
      <origin rpy="0 0 0" xyz="0.0 0.0 0.0"/>
      <inertia ixx="0.010267495893" ixy="0.0" ixz="0.0" iyy="0.010267495893" iyz="0.0" izz="0.00666"/>
    </inertial>
  </link>

  <joint name="arm_shoulder_lift_joint" type="revolute">
    <parent link="arm_shoulder_link"/>
    <child link="arm_upper_arm_link"/>
    <origin rpy="0.0 1.570795 0.0" xyz="0.0 0.13585 0.0"/>
    <axis xyz="0 1 0"/>
    <limit effort="150.0" lower="-3.14159" upper="3.14159" velocity="3.15"/>
    <dynamics damping="0.0" friction="0.0"/>
  </joint>

  <link name="arm_upper_arm_link">
    <visual>
      <geometry>
        <mesh filename="package://mm_description/meshes/ur5/visual/upperarm.dae"/>
      </geometry>
      <material name="LightGrey">
        <color rgba="0.7 0.7 0.7 1.0"/>
      </material>
    </visual>
    <collision>
      <geometry>
        <mesh filename="package://mm_description/meshes/ur5/collision/upperarm.stl"/>
      </geometry>
    </collision>
    <inertial>
      <mass value="8.393"/>
      <origin rpy="0 0 0" xyz="0.0 0.0 0.28"/>
      <inertia ixx="0.22689067591" ixy="0.0" ixz="0.0" iyy="0.22689067591" iyz="0.0" izz="0.0151074"/>
    </inertial>
  </link>

  <joint name="arm_elbow_joint" type="revolute">
    <parent link="arm_upper_arm_link"/>
    <child link="arm_forearm_link"/>
    <origin rpy="0.0 0.0 0.0" xyz="0.0 -0.1197 0.425"/>
    <axis xyz="0 1 0"/>
    <limit effort="150.0" lower="-3.14159" upper="3.14159" velocity="3.15"/>
    <dynamics damping="0.0" friction="0.0"/>
  </joint>

  <link name="arm_forearm_link">
    <visual>
      <geometry>
        <mesh filename="package://mm_description/meshes/ur5/visual/forearm.dae"/>
      </geometry>
      <material name="LightGrey">
        <color rgba="0.7 0.7 0.7 1.0"/>
      </material>
    </visual>
    <collision>
      <geometry>
        <mesh filename="package://mm_description/meshes/ur5/collision/forearm.stl"/>
      </geometry>
    </collision>
    <inertial>
      <mass value="2.275"/>
      <origin rpy="0 0 0" xyz="0.0 0.0 0.25"/>
      <inertia ixx="0.049443313556" ixy="0.0" ixz="0.0" iyy="0.049443313556" iyz="0.0" izz="0.004095"/>
    </inertial>
  </link>
  <joint name="arm_wrist_1_joint" type="revolute">
    <parent link="arm_forearm_link"/>
    <child link="arm_wrist_1_link"/>
    <origin rpy="0.0 1.570795 0.0" xyz="0.0 0.0 0.39225"/>
    <axis xyz="0 1 0"/>
    <limit effort="28.0" lower="-3.14159" upper="3.14159" velocity="3.2"/>
    <dynamics damping="0.0" friction="0.0"/>
  </joint>
  <link name="arm_wrist_1_link">
    <visual>
      <geometry>
        <mesh filename="package://mm_description/meshes/ur5/visual/wrist1.dae"/>
      </geometry>
      <material name="LightGrey">
        <color rgba="0.7 0.7 0.7 1.0"/>
      </material>
    </visual>
    <collision>
      <geometry>
        <mesh filename="package://mm_description/meshes/ur5/collision/wrist1.stl"/>
      </geometry>
    </collision>
    <inertial>
      <mass value="1.219"/>
      <origin rpy="0 0 0" xyz="0.0 0.0 0.0"/>
      <inertia ixx="0.00255989897604" ixy="0.0" ixz="0.0" iyy="0.00255989897604" iyz="0.0" izz="0.0021942"/>
    </inertial>
  </link>
  <joint name="arm_wrist_2_joint" type="revolute">
    <parent link="arm_wrist_1_link"/>
    <child link="arm_wrist_2_link"/>
    <origin rpy="0.0 0.0 0.0" xyz="0.0 0.093 0.0"/>
    <axis xyz="0 0 1"/>
    <limit effort="28.0" lower="-3.14159" upper="3.14159" velocity="3.2"/>
    <dynamics damping="0.0" friction="0.0"/>
  </joint>
  <link name="arm_wrist_2_link">
    <visual>
      <geometry>
        <mesh filename="package://mm_description/meshes/ur5/visual/wrist2.dae"/>
      </geometry>
      <material name="LightGrey">
        <color rgba="0.7 0.7 0.7 1.0"/>
      </material>
    </visual>
    <collision>
      <geometry>
        <mesh filename="package://mm_description/meshes/ur5/collision/wrist2.stl"/>
      </geometry>
    </collision>
    <inertial>
      <mass value="1.219"/>
      <origin rpy="0 0 0" xyz="0.0 0.0 0.0"/>
      <inertia ixx="0.00255989897604" ixy="0.0" ixz="0.0" iyy="0.00255989897604" iyz="0.0" izz="0.0021942"/>
    </inertial>
  </link>
  <joint name="arm_wrist_3_joint" type="revolute">
    <parent link="arm_wrist_2_link"/>
    <child link="arm_wrist_3_link"/>
    <origin rpy="0.0 0.0 0.0" xyz="0.0 0.0 0.09465"/>
    <axis xyz="0 1 0"/>
    <limit effort="28.0" lower="-3.14159" upper="3.14159" velocity="3.2"/>
    <dynamics damping="0.0" friction="0.0"/>
  </joint>
  <link name="arm_wrist_3_link">
    <visual>
      <geometry>
        <mesh filename="package://mm_description/meshes/ur5/visual/wrist3.dae"/>
      </geometry>
      <material name="LightGrey">
        <color rgba="0.7 0.7 0.7 1.0"/>
      </material>
    </visual>
    <collision>
      <geometry>
        <mesh filename="package://mm_description/meshes/ur5/collision/wrist3.stl"/>
      </geometry>
    </collision>
    <inertial>
      <mass value="0.1879"/>
      <origin rpy="0 0 0" xyz="0.0 0.0 0.0"/>
      <inertia ixx="0.000394589842164" ixy="0.0" ixz="0.0" iyy="0.000394589842164" iyz="0.0" izz="0.00033822"/>
    </inertial>
  </link>
  <joint name="arm_ee_fixed_joint" type="fixed">
    <parent link="arm_wrist_3_link"/>
    <child link="arm_ee_link"/>
    <origin rpy="0.0 0.0 1.570795" xyz="0.0 0.0823 0.0"/>
  </joint>
  <link name="arm_ee_link">
    <collision>
      <geometry>
        <box size="0.01 0.01 0.01"/>
      </geometry>
      <origin rpy="0 0 0" xyz="-0.01 0 0"/>
    </collision>
  </link>
  <transmission name="arm_shoulder_pan_trans">
    <type>transmission_interface/SimpleTransmission</type>
    <joint name="arm_shoulder_pan_joint">
      <hardwareInterface>hardware_interface/PositionJointInterface</hardwareInterface>
    </joint>
    <actuator name="arm_shoulder_pan_motor">
      <mechanicalReduction>1</mechanicalReduction>
    </actuator>
  </transmission>
  <transmission name="arm_shoulder_lift_trans">
    <type>transmission_interface/SimpleTransmission</type>
    <joint name="arm_shoulder_lift_joint">
      <hardwareInterface>hardware_interface/PositionJointInterface</hardwareInterface>
    </joint>
    <actuator name="arm_shoulder_lift_motor">
      <mechanicalReduction>1</mechanicalReduction>
    </actuator>
  </transmission>
  <transmission name="arm_elbow_trans">
    <type>transmission_interface/SimpleTransmission</type>
    <joint name="arm_elbow_joint">
      <hardwareInterface>hardware_interface/PositionJointInterface</hardwareInterface>
    </joint>
    <actuator name="arm_elbow_motor">
      <mechanicalReduction>1</mechanicalReduction>
    </actuator>
  </transmission>
  <transmission name="arm_wrist_1_trans">
    <type>transmission_interface/SimpleTransmission</type>
    <joint name="arm_wrist_1_joint">
      <hardwareInterface>hardware_interface/PositionJointInterface</hardwareInterface>
    </joint>
    <actuator name="arm_wrist_1_motor">
      <mechanicalReduction>1</mechanicalReduction>
    </actuator>
  </transmission>
  <transmission name="arm_wrist_2_trans">
    <type>transmission_interface/SimpleTransmission</type>
    <joint name="arm_wrist_2_joint">
      <hardwareInterface>hardware_interface/PositionJointInterface</hardwareInterface>
    </joint>
    <actuator name="arm_wrist_2_motor">
      <mechanicalReduction>1</mechanicalReduction>
    </actuator>
  </transmission>
  <transmission name="arm_wrist_3_trans">
    <type>transmission_interface/SimpleTransmission</type>
    <joint name="arm_wrist_3_joint">
      <hardwareInterface>hardware_interface/PositionJointInterface</hardwareInterface>
    </joint>
    <actuator name="arm_wrist_3_motor">
      <mechanicalReduction>1</mechanicalReduction>
    </actuator>
  </transmission>


  <!-- nothing to do here at the moment -->
  <!-- ROS base_link to UR 'Base' Coordinates transform -->
  <link name="arm_base"/>
  <joint name="arm_base_link-base_fixed_joint" type="fixed">
    <!-- NOTE: this rotation is only needed as long as base_link itself is
                 not corrected wrt the real robot (ie: rotated over 180
                 degrees)
      -->
    <origin rpy="0 0 0" xyz="0.127128 0.0 0.15"/>
    <parent link="arm_base_link"/>
    <child link="arm_base"/>
  </joint>
  <!-- Frame coincident with all-zeros TCP on UR controller -->
  <link name="arm_tool0"/>
  <joint name="arm_wrist_3_link-tool0_fixed_joint" type="fixed">
    <origin rpy="-1.570795 0 0" xyz="0 0.0823 0"/>
    <parent link="arm_wrist_3_link"/>
    <child link="arm_tool0"/>
  </joint>



<!--############################################ Mobile base ##################################################-->
<link name="base_link">
    <inertial>
      <origin
        xyz="0.0030946 4.78250032638821E-11 0.053305"
        rpy="0 0 0" />
      <mass
        value="47.873" />
      <inertia
        ixx="0.774276574699151"
        ixy="-1.03781944357671E-10"
        ixz="0.00763014265820928"
        iyy="1.64933255189991"
        iyz="1.09578155845563E-12"
        izz="2.1239326987473" />
    </inertial>
    <visual>
      <origin
        xyz="0 0 0"
        rpy="1.5707963267949 0 3.14" />
      <geometry>
        <mesh filename="package://robot_description/meshes/robot_base.stl" />
      </geometry>
      <material
        name="LightGrey">
          <color rgba="0.7 0.7 0.7 1.0"/>
      </material>
    </visual>
    <collision>
      <origin
        xyz="0 0 0"
        rpy="1.5707963267949 0 3.14" />
      <geometry>
        <mesh filename="package://robot_description/meshes/robot_base.stl" />
      </geometry>
    </collision>
  </link>

<link name="front_left_wheel">
    <inertial>
      <origin
        xyz="-4.1867E-18 0.0068085 -1.65658661799998E-18"
        rpy="0 0 0" />
      <mass
        value="2.6578" />
      <inertia
        ixx="0.00856502765719703"
        ixy="1.5074118157338E-19"
        ixz="-4.78150098725052E-19"
        iyy="0.013670640432096"
        iyz="-2.68136447099727E-19"
        izz="0.00856502765719703" />
    </inertial>
    <visual>
      <origin
        xyz="0 0 0"
        rpy="1.5707963267949 0 0" />
      <geometry>
        <mesh filename="package://robot_description/meshes/wheel.stl" />
      </geometry>
      <material
        name="Darkgrey">
           <color rgba="0.1 0.1 0.1 1.0"/>
      </material>
    </visual>
    <collision>
      <origin
        xyz="0 0 0"
        rpy="1.5707963267949 0 0" />
      <geometry>
        <mesh filename="package://robot_description/meshes/wheel.stl" />
      </geometry>
    </collision>
  </link>

<link name="front_right_wheel">
    <inertial>
      <origin
        xyz="-4.1867E-18 0.0068085 -1.65658661799998E-18"
        rpy="0 0 0" />
      <mass
        value="2.6578" />
      <inertia
        ixx="0.00856502765719703"
        ixy="1.5074118157338E-19"
        ixz="-4.78150098725052E-19"
        iyy="0.013670640432096"
        iyz="-2.68136447099727E-19"
        izz="0.00856502765719703" />
    </inertial>
    <visual>
      <origin
        xyz="0 0 0"
        rpy="1.5707963267949 0 0" />
      <geometry>
        <mesh filename="package://robot_description/meshes/wheel.stl" />
      </geometry>
      <material
        name="Darkgrey">
          <color rgba="0.1 0.1 0.1 1.0"/>
      </material>
    </visual>
    <collision>
      <origin
        xyz="0 0 0"
        rpy="1.5707963267949 0 0" />
      <geometry>
        <mesh filename="package://robot_description/meshes/wheel.stl" />
      </geometry>
    </collision>
  </link>

<link name="rear_left_wheel">
    <inertial>
      <origin
        xyz="-4.1867E-18 0.0068085 -1.65658661799998E-18"
        rpy="0 0 0" />
      <mass
        value="2.6578" />
      <inertia
        ixx="0.00856502765719703"
        ixy="1.5074118157338E-19"
        ixz="-4.78150098725052E-19"
        iyy="0.013670640432096"
        iyz="-2.68136447099727E-19"
        izz="0.00856502765719703" />
    </inertial>
    <visual>
      <origin
        xyz="0 0 0"
        rpy="1.5707963267949 0 0" />
      <geometry>
        <mesh filename="package://robot_description/meshes/wheel.stl" />
      </geometry>
      <material
        name="Darkgrey">
      <color rgba="0.1 0.1 0.1 1.0"/>
      </material>
    </visual>
    <collision>
      <origin
        xyz="0 0 0"
        rpy="1.5707963267949 0 0" />
      <geometry>
        <mesh filename="package://robot_description/meshes/wheel.stl" />
      </geometry>
    </collision>
  </link>

<link name="rear_right_wheel">
    <inertial>
      <origin
        xyz="-4.1867E-18 0.0068085 -1.65658661799998E-18"
        rpy="0 0 0" />
      <mass
        value="2.6578" />
      <inertia
        ixx="0.00856502765719703"
        ixy="1.5074118157338E-19"
        ixz="-4.78150098725052E-19"
        iyy="0.013670640432096"
        iyz="-2.68136447099727E-19"
        izz="0.00856502765719703" />
    </inertial>
    <visual>
      <origin
        xyz="0 0 0"
        rpy="1.5707963267949 0 0" />
      <geometry>
        <mesh filename="package://robot_description/meshes/wheel.stl" />
      </geometry>
      <material
        name="Darkgrey">
       <color rgba="0.1 0.1 0.1 1.0"/>
      </material>
    </visual>
    <collision>
      <origin
        xyz="0 0 0"
        rpy="1.5707963267949 0 0" />
      <geometry>
        <mesh filename="package://robot_description/meshes/wheel.stl" />
      </geometry>
    </collision>
  </link>


<joint name="front_left_wheel_joint" type="continuous">
    <axis xyz="0 1 0"/>
    <parent link ="base_link"/>
    <child link ="front_left_wheel"/>
    <origin rpy ="0 0 0" xyz= "0.220 0.250 0"/>
  </joint>


<joint name="front_right_wheel_joint" type="continuous">
    <axis xyz="0 1 0"/>
    <parent link ="base_link"/>
    <child link ="front_right_wheel"/>
    <origin rpy ="0 0 0" xyz= "0.220 -0.250 0"/>
  </joint>

<joint name="rear_left_wheel_joint" type="continuous">
    <axis xyz="0 1 0"/>
    <parent link ="base_link"/>
    <child link ="rear_left_wheel"/>
    <origin rpy ="0 0 0" xyz= "-0.220 0.250 0"/>
  </joint>

<joint name="rear_right_wheel_joint" type="continuous">
    <axis xyz="0 1 0"/>
    <parent link ="base_link"/>
    <child link ="rear_right_wheel"/>
    <origin rpy ="0 0 0" xyz= "-0.220 -0.250 0"/>
</joint>

 <link name="base_footprint"/>

    <joint name="base_footprint_joint" type="fixed">
      <origin xyz="0 0 -0.09" rpy="0 0 0" />
      <parent link="base_link" />
      <child link="base_footprint" />
    </joint>
  <!-- mobile base -->

  
  <!-- position controller -->
  <gazebo reference="front_right_wheel">
    <mu1>0.7</mu1>
    <mu2>0.7</mu2>
    <material>Gazebo/Black</material>
  </gazebo>
  <gazebo reference="rear_right_wheel">
    <mu1>0.7</mu1>
    <mu2>0.7</mu2>
    <material>Gazebo/Black</material>
  </gazebo>
  <gazebo reference="rear_left_wheel">
    <mu1>0.7</mu1>
    <mu2>0.7</mu2>
    <material>Gazebo/Black</material>
  </gazebo>
  <gazebo reference="front_left_wheel">
    <mu1>0.7</mu1>
    <mu2>0.7</mu2>
    <material>Gazebo/Black</material>
  </gazebo>

  <gazebo reference="base_hokuyo_link">
    <sensor name="base_hokuyo" type="ray">
      <always_on>true</always_on>
      <update_rate>50</update_rate>
      <pose>0 0 0 0 0 0</pose>
      <visualize>true</visualize>
      <ray>
        <scan>
          <horizontal>
            <samples>150</samples>
            <resolution>1.0</resolution>
            <min_angle>-1.57</min_angle>
            <max_angle>1.57</max_angle>
          </horizontal>
        </scan>
        <range>
          <min>0.05</min>
          <max>10.6</max>
          <resolution>0.36</resolution>
        </range>
      </ray>
      <plugin filename="libgazebo_ros_laser.so" name="gazebo_ros_base_hokuyo_controller">
        <gaussianNoise>0.005</gaussianNoise>
        <alwaysOn>true</alwaysOn>
        <updateRate>50</updateRate>
        <topicName>base_scan</topicName>
        <frameName>/base_hokuyo_link</frameName>
      </plugin>
    </sensor>
  </gazebo>
  <gazebo>
    <plugin filename="libgazebo_ros_planar_move.so" name="base_controller">
      <commandTopic>cmd_vel</commandTopic>
      <odometryTopic>odom</odometryTopic>
      <odometryFrame>odom</odometryFrame>
      <odometryRate>10.0</odometryRate>
      <robotBaseFrame>base_link</robotBaseFrame>
    </plugin>
  </gazebo>

  <joint name="base_link_2_base_hokuyo_link" type="fixed">
    <parent link="base_link"/>
    <child link="base_hokuyo_link"/>
    <origin rpy="0 0 0" xyz="0.34 0 0.12"/>
  </joint>

  <link name="base_hokuyo_link">
    <collision>
      <origin rpy="0 0 0" xyz="0 0 0.005"/>
      <geometry>
        <box size="0.05 0.05 0.08"/>
      </geometry>
    </collision>
    <visual>
      <origin rpy="0 0 0" xyz="0 0 0"/>
      <geometry>
        <mesh filename="package://mm_description/meshes/mobile_base/hokuyo.dae"/>
      </geometry>
    </visual>
    <inertial>
      <mass value="1e-5"/>
      <origin rpy="0 0 0" xyz="0 0 0"/>
      <inertia ixx="1e-6" ixy="0" ixz="0" iyy="1e-6" iyz="0" izz="1e-6"/>
    </inertial>
  </link>

  <joint name="base_link_2_arm_base_link" type="fixed">
    <parent link="base_link"/>
    <child link="arm_base_link"/>
    <origin rpy="0 0 0" xyz="0.127128 0.0 0.15"/>
  </joint>


   

  <link name="xtion1_frame">
    <inertial>
      <mass value="1e-5"/>
      <origin rpy="0 0 0" xyz="0 0 0"/>
      <inertia ixx="1e-6" ixy="0" ixz="0" iyy="1e-6" iyz="0" izz="1e-6"/>
    </inertial>
    <visual>
      <origin rpy="1.57 0 1.57" xyz="0.0 0.0 0"/>
      <geometry>
        <mesh filename="package://mm_description/meshes/sensors/asus_xtion_pro_live_camera.dae" scale="0.001 0.001 0.001"/>
      </geometry>
    </visual>
    <collision>
      <origin rpy="1.57 0 1.57" xyz="0.0 0.0 0"/>
      <geometry>
        <mesh filename="package://mm_description/meshes/sensors/asus_xtion_pro_live_camera.dae" scale="0.001 0.001 0.001"/>
      </geometry>
    </collision>
  </link>

  <joint name="arm_tool0_2_xtion1_frame" type="fixed">
    <parent link="arm_tool0"/>
    <child link="xtion1_frame"/>
    <origin rpy="0 -1.5707963 0 " xyz="-0.05 0 0.0"/>
  </joint>
  <joint name="xtion1_frame_2_xtion1_optical_frame" type="fixed">
    <parent link="xtion1_frame"/>
    <child link="xtion1_optical_frame"/>
    <origin rpy="-1.5707963 0 -1.5707963" xyz="0 0 0"/>
  </joint>

  <link name="xtion1_optical_frame"/>
  <gazebo reference="xtion1_frame">
    <sensor name="xtion1_frame_sensor" type="depth">
      <always_on>true</always_on>
      <update_rate>20.0</update_rate>
      <camera>
        <horizontal_fov>0.994837656667</horizontal_fov>
        <image>
          <format>R8G8B8</format>
          <width>640</width>
          <height>480</height>
        </image>
        <clip>
          <near>0.01</near>
          <far>5</far>
        </clip>
      </camera>

      <plugin filename="libgazebo_ros_openni_kinect.so" name="xtion1_frame_controller">
        <alwaysOn>true</alwaysOn>
        <updateRate>20.0</updateRate>
        <cameraName>xtion1</cameraName>
        <imageTopicName>xtion1/ir/image_raw</imageTopicName>
        <cameraInfoTopicName>xtion1/ir/camera_info</cameraInfoTopicName>
        <depthImageTopicName>xtion1/depth/image_raw</depthImageTopicName>
        <depthImageCameraInfoTopicName>xtion1/depth/camera_info</depthImageCameraInfoTopicName>
        <pointCloudTopicName>xtion1/depth/points</pointCloudTopicName>
        <frameName>xtion1_optical_frame</frameName>
        <!--frameName>${name}_frame</frameName-->
        <pointCloudCutoff>0.5</pointCloudCutoff>
        <distortionK1>0.0000000</distortionK1>
        <distortionK2>0.0000000</distortionK2>
        <distortionK3>0.0000000</distortionK3>
        <distortionT1>0.0000000</distortionT1>
        <distortionT2>0.0000000</distortionT2>
        <CxPrime>0</CxPrime>
        <Cx>0</Cx>
        <Cy>0</Cy>
        <focalLength>0</focalLength>
        <hackBaseline>0</hackBaseline>
      </plugin>
    </sensor>
    
  </gazebo>
</robot>

