<sdf version='1.6'>
  <world name='default'>
    <light name='sun' type='directional'>
      <cast_shadows>1</cast_shadows>
      <pose frame=''>0 0 10 0 -0 0</pose>
      <diffuse>0.8 0.8 0.8 1</diffuse>
      <specular>0.1 0.1 0.1 1</specular>
      <attenuation>
        <range>1000</range>
        <constant>0.9</constant>
        <linear>0.01</linear>
        <quadratic>0.001</quadratic>
      </attenuation>
      <direction>-0.5 0.5 -1</direction>
    </light>
    <model name='ground_plane'>
      <static>1</static>
      <link name='link'>
        <collision name='collision'>
          <geometry>
            <plane>
              <normal>0 0 1</normal>
              <size>100 100</size>
            </plane>
          </geometry>
          <surface>
            <friction>
              <ode>
                <mu>100</mu>
                <mu2>50</mu2>
              </ode>
              <torsional>
                <ode/>
              </torsional>
            </friction>
            <contact>
              <ode/>
            </contact>
            <bounce/>
          </surface>
          <max_contacts>10</max_contacts>
        </collision>
        <visual name='visual'>
          <cast_shadows>0</cast_shadows>
          <geometry>
            <plane>
              <normal>0 0 1</normal>
              <size>100 100</size>
            </plane>
          </geometry>
          <material>
            <script>
              <uri>file://media/materials/scripts/gazebo.material</uri>
              <name>Gazebo/Grey</name>
            </script>
          </material>
        </visual>
        <self_collide>0</self_collide>
        <kinematic>0</kinematic>
        <gravity>1</gravity>
      </link>
    </model>
    <gravity>0 0 -9.8</gravity>
    <magnetic_field>6e-06 2.3e-05 -4.2e-05</magnetic_field>
    <atmosphere type='adiabatic'/>
    <physics name='default_physics' default='0' type='ode'>
      <max_step_size>0.001</max_step_size>
      <real_time_factor>1</real_time_factor>
      <real_time_update_rate>1000</real_time_update_rate>
    </physics>
    <scene>
      <ambient>0.4 0.4 0.4 1</ambient>
      <background>0.7 0.7 0.7 1</background>
      <shadows>1</shadows>
    </scene>
    <spherical_coordinates>
      <surface_model>EARTH_WGS84</surface_model>
      <latitude_deg>0</latitude_deg>
      <longitude_deg>0</longitude_deg>
      <elevation>0</elevation>
      <heading_deg>0</heading_deg>
    </spherical_coordinates>
    <state world_name='default'>
      <sim_time>237 385000000</sim_time>
      <real_time>187 922897017</real_time>
      <wall_time>1612243244 554522453</wall_time>
      <iterations>120566</iterations>
      <model name='ar_marker'>
        <pose frame=''>0.193154 11.4466 0 0 -0 0</pose>
        <scale>1 1 1</scale>
        <link name='link'>
          <pose frame=''>0.193154 11.4466 0 0 -0 0</pose>
          <velocity>0 0 0 0 -0 0</velocity>
          <acceleration>0 0 0 0 -0 0</acceleration>
          <wrench>0 0 0 0 -0 0</wrench>
        </link>
      </model>
      <model name='ground_plane'>
        <pose frame=''>0 0 0 0 -0 0</pose>
        <scale>1 1 1</scale>
        <link name='link'>
          <pose frame=''>0 0 0 0 -0 0</pose>
          <velocity>0 0 0 0 -0 0</velocity>
          <acceleration>0 0 0 0 -0 0</acceleration>
          <wrench>0 0 0 0 -0 0</wrench>
        </link>
      </model>
      <model name='mobile_manipulator'>
        <pose frame=''>4.99798 4.01136 0.099795 -1.3e-05 0.000622 0.023994</pose>
        <scale>1 1 1</scale>
        <link name='arm_base'>
          <pose frame=''>5.19801 4.01616 0.244671 -2e-06 0.00062 0.048464</pose>
          <velocity>-6.2e-05 0.000111 0.000164 -0.00057 -0.00037 -0.000154</velocity>
          <acceleration>-0.03191 0.065173 0.071734 2.92966 0.19342 -2.92094</acceleration>
          <wrench>-0.051069 0.104303 0.114803 0 -0 0</wrench>
        </link>
        <link name='base_link'>
          <pose frame=''>4.99798 4.01136 0.099795 -1.3e-05 0.000622 0.023994</pose>
          <velocity>5.5e-05 7.1e-05 3e-06 -0.000589 -0.000825 -0.000225</velocity>
          <acceleration>-0.012613 0.047564 -0.017132 -0.280835 -0.368073 -0.040027</acceleration>
          <wrench>-0.603815 2.27702 -0.820145 0 -0 0</wrench>
        </link>
        <link name='bicep'>
          <pose frame=''>5.14653 4.01367 0.447413 0.000623 0.165369 1.61937</pose>
          <velocity>-0.000223 0.000232 0.000122 0.000335 0.000758 -2.3e-05</velocity>
          <acceleration>-0.161259 0.101131 0.058306 -1.67639 -0.429404 2.7442</acceleration>
          <wrench>-0.180578 0.113246 0.065291 0 -0 0</wrench>
        </link>
        <link name='bottom_wrist'>
          <pose frame=''>5.19643 4.06042 0.712711 0.000632 -0.250058 1.61911</pose>
          <velocity>-0.000283 0.00013 0.000143 0.001052 0.001132 0.000126</velocity>
          <acceleration>-0.22589 0.084027 0.095642 2.91513 1.22683 -1.39839</acceleration>
          <wrench>-0.062619 0.023293 0.026513 0 -0 0</wrench>
        </link>
        <link name='elbow'>
          <pose frame=''>5.19813 4.027 0.843725 -0.005802 -0.249991 1.64512</pose>
          <velocity>-0.000194 -1e-06 7.3e-05 0.001046 0.000923 0.002169</velocity>
          <acceleration>-0.211456 0.006395 0.00136 2.89519 1.19881 2.85967</acceleration>
          <wrench>-0.17941 0.005426 0.001154 0 -0 0</wrench>
        </link>
        <link name='front_left_wheel'>
          <pose frame=''>5.21191 4.26656 0.099655 -1.2e-05 4e-06 0.024127</pose>
          <velocity>0.000112 2.4e-05 1.8e-05 -0.000241 0.001119 -4e-06</velocity>
          <acceleration>0.01716 0.02687 -0.009531 -0.237651 0.170051 -7.6e-05</acceleration>
          <wrench>0.045608 0.071415 -0.025333 0 -0 0</wrench>
        </link>
        <link name='front_right_wheel'>
          <pose frame=''>5.22391 3.76671 0.099661 -1.3e-05 -0.000222 0.023994</pose>
          <velocity>0 2.1e-05 0.000334 -0.00059 -0.000531 -0.000225</velocity>
          <acceleration>-0.002861 0.023753 0.128686 -0.276726 -0.210508 -0.040922</acceleration>
          <wrench>-0.007604 0.063132 0.342023 0 -0 0</wrench>
        </link>
        <link name='rear_left_wheel'>
          <pose frame=''>4.77204 4.25601 0.099928 -1.3e-05 -0.009622 0.023994</pose>
          <velocity>0.000109 0.000122 -0.000327 -0.00059 -0.000531 -0.000224</velocity>
          <acceleration>0.016953 0.042271 -0.169152 -0.276482 -0.2105 -0.04058</acceleration>
          <wrench>0.045058 0.112349 -0.449572 0 -0 0</wrench>
        </link>
        <link name='rear_right_wheel'>
          <pose frame=''>4.78404 3.75615 0.099935 -1e-06 -0.04651 0.023993</pose>
          <velocity>-4e-06 0.000102 -3.4e-05 -0.001028 -0.000107 -0.000132</velocity>
          <acceleration>-0.003474 0.038467 -0.027622 -0.378222 -0.075116 -0.064905</acceleration>
          <wrench>-0.009234 0.102239 -0.073413 0 -0 0</wrench>
        </link>
        <link name='top_wrist'>
          <pose frame=''>5.20077 3.97512 1.04713 -3.13592 0.137297 -1.49714</pose>
          <velocity>6.2e-05 -0.000213 1.2e-05 0.007867 0.001379 0.00221</velocity>
          <acceleration>-0.354871 -0.042494 0.070486 -1.80333 -0.347974 0.579095</acceleration>
          <wrench>-0.098374 -0.01178 0.019539 0 -0 0</wrench>
        </link>
      </model>
      <model name='nee'>
        <pose frame=''>0 0 0 1e-06 1e-06 0</pose>
        <scale>1 1 1</scale>
        <link name='link_0'>
          <pose frame=''>0 0 0 1e-06 1e-06 0</pose>
          <velocity>0 0 0 0 -0 0</velocity>
          <acceleration>0 5e-06 -0.070336 -0.675945 0.675945 0</acceleration>
          <wrench>0 5e-06 -0.070336 0 -0 0</wrench>
        </link>
      </model>
      <light name='sun'>
        <pose frame=''>0 0 10 0 -0 0</pose>
      </light>
    </state>
    <gui fullscreen='0'>
      <camera name='user_camera'>
        <pose frame=''>17.3382 4.77804 3.46598 -0.000265 0.189129 2.77788</pose>
        <view_controller>orbit</view_controller>
        <projection_type>perspective</projection_type>
      </camera>
    </gui>
    <model name='mobile_manipulator'>
      <link name='base_link'>
        <pose frame=''>0 0 0 0 -0 0</pose>
        <inertial>
          <pose frame=''>0.003095 0 0.053305 0 -0 0</pose>
          <mass>47.873</mass>
          <inertia>
            <ixx>0.774278</ixx>
            <ixy>-1.03782e-10</ixy>
            <ixz>0.00762993</ixz>
            <iyy>1.64933</iyy>
            <iyz>1.09581e-12</iyz>
            <izz>2.12393</izz>
          </inertia>
        </inertial>
        <collision name='base_link_collision'>
          <pose frame=''>0 0 0 1.5708 -0 3.14</pose>
          <geometry>
            <mesh>
              <scale>1 1 1</scale>
              <uri>/home/sandra/mm_ws/src/robot_description/meshes/robot_base.stl</uri>
            </mesh>
          </geometry>
          <max_contacts>10</max_contacts>
          <surface>
            <contact>
              <ode/>
            </contact>
            <bounce/>
            <friction>
              <torsional>
                <ode/>
              </torsional>
              <ode/>
            </friction>
          </surface>
        </collision>
        <collision name='base_link_fixed_joint_lump__laser_link_collision_1'>
          <pose frame=''>0.35 0 0.115 0 -0 0</pose>
          <geometry>
            <box>
              <size>0.1 0.1 0.1</size>
            </box>
          </geometry>
          <surface>
            <contact>
              <ode/>
            </contact>
            <friction>
              <ode/>
              <torsional>
                <ode/>
              </torsional>
            </friction>
            <bounce/>
          </surface>
          <max_contacts>10</max_contacts>
        </collision>
        <visual name='base_link_visual'>
          <pose frame=''>0 0 0 1.5708 -0 3.14</pose>
          <geometry>
            <mesh>
              <scale>1 1 1</scale>
              <uri>/home/sandra/mm_ws/src/robot_description/meshes/robot_base.stl</uri>
            </mesh>
          </geometry>
        </visual>
        <visual name='base_link_fixed_joint_lump__laser_link_visual_1'>
          <pose frame=''>0.35 0 0.115 0 -0 0</pose>
          <geometry>
            <box>
              <size>0.05 0.05 0.05</size>
            </box>
          </geometry>
          <material>
            <script>
              <uri>__default__</uri>
              <name>__default__</name>
            </script>
          </material>
        </visual>
        <gravity>1</gravity>
        <velocity_decay/>
        <self_collide>0</self_collide>
        <sensor name='laser' type='ray'>
          <visualize>1</visualize>
          <update_rate>40</update_rate>
          <ray>
            <scan>
              <horizontal>
                <samples>720</samples>
                <resolution>1</resolution>
                <min_angle>-1.5708</min_angle>
                <max_angle>1.5708</max_angle>
              </horizontal>
              <vertical>
                <samples>1</samples>
                <min_angle>0</min_angle>
                <max_angle>0</max_angle>
              </vertical>
            </scan>
            <range>
              <min>0.1</min>
              <max>30</max>
              <resolution>0.01</resolution>
            </range>
          </ray>
          <plugin name='gazebo_ros_head_hokuyo_controller' filename='libgazebo_ros_laser.so'>
            <topicName>/scan</topicName>
            <frameName>laser_link</frameName>
            <robotNamespace>/</robotNamespace>
          </plugin>
          <pose frame=''>0.35 0 0.115 0 -0 0</pose>
        </sensor>
        <kinematic>0</kinematic>
      </link>
      <link name='arm_base'>
        <pose frame=''>0.2 0 0.145 0 -0 0</pose>
        <inertial>
          <pose frame=''>0 -0.063005 -0 0 -0 0</pose>
          <mass>1.6004</mass>
          <inertia>
            <ixx>0.00552197</ixx>
            <ixy>7.95506e-10</ixy>
            <ixz>-1.34378e-09</ixz>
            <iyy>0.00352397</iyy>
            <iyz>-1.10072e-08</iyz>
            <izz>0.0055374</izz>
          </inertia>
        </inertial>
        <collision name='arm_base_collision'>
          <pose frame=''>0 0 0 0 -0 0</pose>
          <geometry>
            <mesh>
              <scale>1 1 1</scale>
              <uri>/home/sandra/mm_ws/src/robot_description/meshes/arm_base.stl</uri>
            </mesh>
          </geometry>
          <max_contacts>10</max_contacts>
          <surface>
            <contact>
              <ode/>
            </contact>
            <bounce/>
            <friction>
              <torsional>
                <ode/>
              </torsional>
              <ode/>
            </friction>
          </surface>
        </collision>
        <visual name='arm_base_visual'>
          <pose frame=''>0 0 0 0 -0 0</pose>
          <geometry>
            <mesh>
              <scale>1 1 1</scale>
              <uri>/home/sandra/mm_ws/src/robot_description/meshes/arm_base.stl</uri>
            </mesh>
          </geometry>
        </visual>
        <self_collide>0</self_collide>
        <kinematic>0</kinematic>
        <gravity>1</gravity>
      </link>
      <joint name='arm_base_joint' type='revolute'>
        <child>arm_base</child>
        <parent>base_link</parent>
        <axis>
          <xyz>0 0 1</xyz>
          <limit>
            <lower>-1e+16</lower>
            <upper>1e+16</upper>
          </limit>
          <dynamics>
            <spring_reference>0</spring_reference>
            <spring_stiffness>0</spring_stiffness>
          </dynamics>
          <use_parent_model_frame>1</use_parent_model_frame>
        </axis>
      </joint>
      <link name='bicep'>
        <pose frame=''>0.14834 0 0.34771 0 -0 1.5708</pose>
        <inertial>
          <pose frame=''>0.12821 4e-06 0.052492 0 -0 0</pose>
          <mass>1.1198</mass>
          <inertia>
            <ixx>0.0012474</ixx>
            <ixy>-5.4004e-07</ixy>
            <ixz>-0.0013148</ixz>
            <iyy>0.0072923</iyy>
            <iyz>-1.8586e-07</iyz>
            <izz>0.0068178</izz>
          </inertia>
        </inertial>
        <collision name='bicep_collision'>
          <pose frame=''>0 0 0 3.14159 -1.57079 3.14159</pose>
          <geometry>
            <mesh>
              <scale>1 1 1</scale>
              <uri>/home/sandra/mm_ws/src/robot_description/meshes/bicep.stl</uri>
            </mesh>
          </geometry>
          <max_contacts>10</max_contacts>
          <surface>
            <contact>
              <ode/>
            </contact>
            <bounce/>
            <friction>
              <torsional>
                <ode/>
              </torsional>
              <ode/>
            </friction>
          </surface>
        </collision>
        <visual name='bicep_visual'>
          <pose frame=''>0 0 0 3.14159 -1.57079 3.14159</pose>
          <geometry>
            <mesh>
              <scale>1 1 1</scale>
              <uri>/home/sandra/mm_ws/src/robot_description/meshes/bicep.stl</uri>
            </mesh>
          </geometry>
        </visual>
        <self_collide>0</self_collide>
        <kinematic>0</kinematic>
        <gravity>1</gravity>
      </link>
      <joint name='shoulder_joint' type='revolute'>
        <child>bicep</child>
        <parent>arm_base</parent>
        <axis>
          <xyz>-1 -4e-06 0</xyz>
          <limit>
            <lower>-1e+16</lower>
            <upper>1e+16</upper>
          </limit>
          <dynamics>
            <spring_reference>0</spring_reference>
            <spring_stiffness>0</spring_stiffness>
          </dynamics>
          <use_parent_model_frame>1</use_parent_model_frame>
        </axis>
      </joint>
      <link name='bottom_wrist'>
        <pose frame=''>0.20028 0 0.61671 0 -0 1.5708</pose>
        <inertial>
          <pose frame=''>-0 -0.069257 -0 0 -0 0</pose>
          <mass>0.27721</mass>
          <inertia>
            <ixx>0.00104291</ixx>
            <ixy>4.37155e-09</ixy>
            <ixz>-2.4505e-09</ixz>
            <iyy>0.000380518</iyy>
            <iyz>-7.5601e-09</iyz>
            <izz>0.00106007</izz>
          </inertia>
        </inertial>
        <collision name='bottom_wrist_collision'>
          <pose frame=''>0 0 0.13522 3.14 -0 1.5708</pose>
          <geometry>
            <mesh>
              <scale>1 1 1</scale>
              <uri>/home/sandra/mm_ws/src/robot_description/meshes/wrist.stl</uri>
            </mesh>
          </geometry>
          <max_contacts>10</max_contacts>
          <surface>
            <contact>
              <ode/>
            </contact>
            <bounce/>
            <friction>
              <torsional>
                <ode/>
              </torsional>
              <ode/>
            </friction>
          </surface>
        </collision>
        <visual name='bottom_wrist_visual'>
          <pose frame=''>0 0 0.13522 3.14 -0 1.5708</pose>
          <geometry>
            <mesh>
              <scale>1 1 1</scale>
              <uri>/home/sandra/mm_ws/src/robot_description/meshes/wrist.stl</uri>
            </mesh>
          </geometry>
        </visual>
        <self_collide>0</self_collide>
        <kinematic>0</kinematic>
        <gravity>1</gravity>
      </link>
      <joint name='bottom_wrist_joint' type='revolute'>
        <child>bottom_wrist</child>
        <parent>bicep</parent>
        <axis>
          <xyz>-1 -4e-06 0</xyz>
          <limit>
            <lower>-1e+16</lower>
            <upper>1e+16</upper>
          </limit>
          <dynamics>
            <spring_reference>0</spring_reference>
            <spring_stiffness>0</spring_stiffness>
          </dynamics>
          <use_parent_model_frame>1</use_parent_model_frame>
        </axis>
      </joint>
      <link name='elbow'>
        <pose frame=''>0.20028 0 0.75193 0 -0 1.5708</pose>
        <inertial>
          <pose frame=''>-0.11109 0 0.046469 0 -0 0</pose>
          <mass>0.84845</mass>
          <inertia>
            <ixx>0.00079656</ixx>
            <ixy>-7.8011e-10</ixy>
            <ixz>0.00053616</ixz>
            <iyy>0.003576</iyy>
            <iyz>4.6326e-10</iyz>
            <izz>0.0033698</izz>
          </inertia>
        </inertial>
        <collision name='elbow_collision'>
          <pose frame=''>0 0.05163 0.20994 3.14159 -1.57079 3.14159</pose>
          <geometry>
            <mesh>
              <scale>1 1 1</scale>
              <uri>/home/sandra/mm_ws/src/robot_description/meshes/elbow.stl</uri>
            </mesh>
          </geometry>
          <max_contacts>10</max_contacts>
          <surface>
            <contact>
              <ode/>
            </contact>
            <bounce/>
            <friction>
              <torsional>
                <ode/>
              </torsional>
              <ode/>
            </friction>
          </surface>
        </collision>
        <visual name='elbow_visual'>
          <pose frame=''>0 0.05163 0.20994 3.14159 -1.57079 3.14159</pose>
          <geometry>
            <mesh>
              <scale>1 1 1</scale>
              <uri>/home/sandra/mm_ws/src/robot_description/meshes/elbow.stl</uri>
            </mesh>
          </geometry>
        </visual>
        <self_collide>0</self_collide>
        <kinematic>0</kinematic>
        <gravity>1</gravity>
      </link>
      <joint name='elbow_joint' type='revolute'>
        <child>elbow</child>
        <parent>bottom_wrist</parent>
        <axis>
          <xyz>0 0 1</xyz>
          <limit>
            <lower>-1e+16</lower>
            <upper>1e+16</upper>
          </limit>
          <dynamics>
            <spring_reference>0</spring_reference>
            <spring_stiffness>0</spring_stiffness>
          </dynamics>
          <use_parent_model_frame>1</use_parent_model_frame>
        </axis>
      </joint>
      <link name='top_wrist'>
        <pose frame=''>0.20028 0 0.96187 0 -0 1.5708</pose>
        <inertial>
          <pose frame=''>-0 -0.069257 -0 0 -0 0</pose>
          <mass>0.27721</mass>
          <inertia>
            <ixx>0.00104291</ixx>
            <ixy>4.37155e-09</ixy>
            <ixz>-2.4505e-09</ixz>
            <iyy>0.000380518</iyy>
            <iyz>-7.5601e-09</iyz>
            <izz>0.00106007</izz>
          </inertia>
        </inertial>
        <collision name='top_wrist_collision'>
          <pose frame=''>0 0 0.13522 3.14 -0 1.5708</pose>
          <geometry>
            <mesh>
              <scale>1 1 1</scale>
              <uri>/home/sandra/mm_ws/src/robot_description/meshes/wrist.stl</uri>
            </mesh>
          </geometry>
          <max_contacts>10</max_contacts>
          <surface>
            <contact>
              <ode/>
            </contact>
            <bounce/>
            <friction>
              <torsional>
                <ode/>
              </torsional>
              <ode/>
            </friction>
          </surface>
        </collision>
        <visual name='top_wrist_visual'>
          <pose frame=''>0 0 0.13522 3.14 -0 1.5708</pose>
          <geometry>
            <mesh>
              <scale>1 1 1</scale>
              <uri>/home/sandra/mm_ws/src/robot_description/meshes/wrist.stl</uri>
            </mesh>
          </geometry>
        </visual>
        <self_collide>0</self_collide>
        <kinematic>0</kinematic>
        <gravity>1</gravity>
      </link>
      <joint name='top_wrist_joint' type='revolute'>
        <child>top_wrist</child>
        <parent>elbow</parent>
        <axis>
          <xyz>-1 -4e-06 0</xyz>
          <limit>
            <lower>-1e+16</lower>
            <upper>1e+16</upper>
          </limit>
          <dynamics>
            <spring_reference>0</spring_reference>
            <spring_stiffness>0</spring_stiffness>
          </dynamics>
          <use_parent_model_frame>1</use_parent_model_frame>
        </axis>
      </joint>
      <link name='front_left_wheel'>
        <pose frame=''>0.22 0.25 0 0 -0 0</pose>
        <inertial>
          <pose frame=''>-0 0.006809 -0 0 -0 0</pose>
          <mass>2.6578</mass>
          <inertia>
            <ixx>0.00856503</ixx>
            <ixy>1.50741e-19</ixy>
            <ixz>-4.7815e-19</ixz>
            <iyy>0.0136706</iyy>
            <iyz>-2.68136e-19</iyz>
            <izz>0.00856503</izz>
          </inertia>
        </inertial>
        <collision name='front_left_wheel_collision'>
          <pose frame=''>0 0 0 1.5708 -0 0</pose>
          <geometry>
            <mesh>
              <scale>1 1 1</scale>
              <uri>/home/sandra/mm_ws/src/robot_description/meshes/wheel.stl</uri>
            </mesh>
          </geometry>
          <surface>
            <contact>
              <ode>
                <kp>1e+07</kp>
                <kd>1</kd>
              </ode>
            </contact>
            <friction>
              <ode>
                <mu>1</mu>
                <mu2>1</mu2>
                <fdir1>1 0 0</fdir1>
              </ode>
              <torsional>
                <ode/>
              </torsional>
            </friction>
            <bounce/>
          </surface>
          <max_contacts>10</max_contacts>
        </collision>
        <visual name='front_left_wheel_visual'>
          <pose frame=''>0 0 0 1.5708 -0 0</pose>
          <geometry>
            <mesh>
              <scale>1 1 1</scale>
              <uri>/home/sandra/mm_ws/src/robot_description/meshes/wheel.stl</uri>
            </mesh>
          </geometry>
          <material>
            <script>
              <uri>__default__</uri>
              <name>__default__</name>
            </script>
          </material>
        </visual>
        <gravity>1</gravity>
        <velocity_decay/>
        <self_collide>0</self_collide>
        <kinematic>0</kinematic>
      </link>
      <joint name='front_left_wheel_joint' type='revolute'>
        <child>front_left_wheel</child>
        <parent>base_link</parent>
        <axis>
          <xyz>0 1 0</xyz>
          <limit>
            <lower>-1e+16</lower>
            <upper>1e+16</upper>
          </limit>
          <dynamics>
            <spring_reference>0</spring_reference>
            <spring_stiffness>0</spring_stiffness>
          </dynamics>
          <use_parent_model_frame>1</use_parent_model_frame>
        </axis>
      </joint>
      <link name='front_right_wheel'>
        <pose frame=''>0.22 -0.25 0 0 -0 0</pose>
        <inertial>
          <pose frame=''>-0 0.006809 -0 0 -0 0</pose>
          <mass>2.6578</mass>
          <inertia>
            <ixx>0.00856503</ixx>
            <ixy>1.50741e-19</ixy>
            <ixz>-4.7815e-19</ixz>
            <iyy>0.0136706</iyy>
            <iyz>-2.68136e-19</iyz>
            <izz>0.00856503</izz>
          </inertia>
        </inertial>
        <collision name='front_right_wheel_collision'>
          <pose frame=''>0 0 0 1.5708 -0 0</pose>
          <geometry>
            <mesh>
              <scale>1 1 1</scale>
              <uri>/home/sandra/mm_ws/src/robot_description/meshes/wheel.stl</uri>
            </mesh>
          </geometry>
          <surface>
            <contact>
              <ode>
                <kp>1e+07</kp>
                <kd>1</kd>
              </ode>
            </contact>
            <friction>
              <ode>
                <mu>1</mu>
                <mu2>1</mu2>
                <fdir1>1 0 0</fdir1>
              </ode>
              <torsional>
                <ode/>
              </torsional>
            </friction>
            <bounce/>
          </surface>
          <max_contacts>10</max_contacts>
        </collision>
        <visual name='front_right_wheel_visual'>
          <pose frame=''>0 0 0 1.5708 -0 0</pose>
          <geometry>
            <mesh>
              <scale>1 1 1</scale>
              <uri>/home/sandra/mm_ws/src/robot_description/meshes/wheel.stl</uri>
            </mesh>
          </geometry>
          <material>
            <script>
              <uri>__default__</uri>
              <name>__default__</name>
            </script>
          </material>
        </visual>
        <gravity>1</gravity>
        <velocity_decay/>
        <self_collide>0</self_collide>
        <kinematic>0</kinematic>
      </link>
      <joint name='front_right_wheel_joint' type='revolute'>
        <child>front_right_wheel</child>
        <parent>base_link</parent>
        <axis>
          <xyz>0 1 0</xyz>
          <limit>
            <lower>-1e+16</lower>
            <upper>1e+16</upper>
          </limit>
          <dynamics>
            <spring_reference>0</spring_reference>
            <spring_stiffness>0</spring_stiffness>
          </dynamics>
          <use_parent_model_frame>1</use_parent_model_frame>
        </axis>
      </joint>
      <link name='rear_left_wheel'>
        <pose frame=''>-0.22 0.25 0 0 -0 0</pose>
        <inertial>
          <pose frame=''>-0 0.006809 -0 0 -0 0</pose>
          <mass>2.6578</mass>
          <inertia>
            <ixx>0.00856503</ixx>
            <ixy>1.50741e-19</ixy>
            <ixz>-4.7815e-19</ixz>
            <iyy>0.0136706</iyy>
            <iyz>-2.68136e-19</iyz>
            <izz>0.00856503</izz>
          </inertia>
        </inertial>
        <collision name='rear_left_wheel_collision'>
          <pose frame=''>0 0 0 1.5708 -0 0</pose>
          <geometry>
            <mesh>
              <scale>1 1 1</scale>
              <uri>/home/sandra/mm_ws/src/robot_description/meshes/wheel.stl</uri>
            </mesh>
          </geometry>
          <surface>
            <contact>
              <ode>
                <kp>1e+07</kp>
                <kd>1</kd>
              </ode>
            </contact>
            <friction>
              <ode>
                <mu>1</mu>
                <mu2>1</mu2>
                <fdir1>1 0 0</fdir1>
              </ode>
              <torsional>
                <ode/>
              </torsional>
            </friction>
            <bounce/>
          </surface>
          <max_contacts>10</max_contacts>
        </collision>
        <visual name='rear_left_wheel_visual'>
          <pose frame=''>0 0 0 1.5708 -0 0</pose>
          <geometry>
            <mesh>
              <scale>1 1 1</scale>
              <uri>/home/sandra/mm_ws/src/robot_description/meshes/wheel.stl</uri>
            </mesh>
          </geometry>
          <material>
            <script>
              <uri>__default__</uri>
              <name>__default__</name>
            </script>
          </material>
        </visual>
        <velocity_decay/>
        <gravity>1</gravity>
        <velocity_decay/>
        <self_collide>0</self_collide>
        <kinematic>0</kinematic>
      </link>
      <joint name='rear_left_wheel_joint' type='revolute'>
        <child>rear_left_wheel</child>
        <parent>base_link</parent>
        <axis>
          <xyz>0 1 0</xyz>
          <limit>
            <lower>-1e+16</lower>
            <upper>1e+16</upper>
          </limit>
          <dynamics>
            <spring_reference>0</spring_reference>
            <spring_stiffness>0</spring_stiffness>
          </dynamics>
          <use_parent_model_frame>1</use_parent_model_frame>
        </axis>
      </joint>
      <link name='rear_right_wheel'>
        <pose frame=''>-0.22 -0.25 0 0 -0 0</pose>
        <inertial>
          <pose frame=''>-0 0.006809 -0 0 -0 0</pose>
          <mass>2.6578</mass>
          <inertia>
            <ixx>0.00856503</ixx>
            <ixy>1.50741e-19</ixy>
            <ixz>-4.7815e-19</ixz>
            <iyy>0.0136706</iyy>
            <iyz>-2.68136e-19</iyz>
            <izz>0.00856503</izz>
          </inertia>
        </inertial>
        <collision name='rear_right_wheel_collision'>
          <pose frame=''>0 0 0 1.5708 -0 0</pose>
          <geometry>
            <mesh>
              <scale>1 1 1</scale>
              <uri>/home/sandra/mm_ws/src/robot_description/meshes/wheel.stl</uri>
            </mesh>
          </geometry>
          <max_contacts>10</max_contacts>
          <surface>
            <contact>
              <ode/>
            </contact>
            <bounce/>
            <friction>
              <torsional>
                <ode/>
              </torsional>
              <ode/>
            </friction>
          </surface>
        </collision>
        <visual name='rear_right_wheel_visual'>
          <pose frame=''>0 0 0 1.5708 -0 0</pose>
          <geometry>
            <mesh>
              <scale>1 1 1</scale>
              <uri>/home/sandra/mm_ws/src/robot_description/meshes/wheel.stl</uri>
            </mesh>
          </geometry>
        </visual>
        <self_collide>0</self_collide>
        <kinematic>0</kinematic>
        <gravity>1</gravity>
      </link>
      <joint name='rear_right_wheel_joint' type='revolute'>
        <child>rear_right_wheel</child>
        <parent>base_link</parent>
        <axis>
          <xyz>0 1 0</xyz>
          <limit>
            <lower>-1e+16</lower>
            <upper>1e+16</upper>
          </limit>
          <dynamics>
            <spring_reference>0</spring_reference>
            <spring_stiffness>0</spring_stiffness>
          </dynamics>
          <use_parent_model_frame>1</use_parent_model_frame>
        </axis>
      </joint>
      <plugin name='gazebo_ros_control' filename='libgazebo_ros_control.so'>
        <robotNamespace>/</robotNamespace>
        <controlPeriod>0.001</controlPeriod>
        <legacyModeNS>false</legacyModeNS>
      </plugin>
      <plugin name='joint_state_publisher' filename='libgazebo_ros_joint_state_publisher.so'>
        <jointName>arm_base_joint, shoulder_joint, bottom_wrist_joint, elbow_joint, bottom_wrist_joint</jointName>
        <robotNamespace>/</robotNamespace>
      </plugin>
      <static>0</static>
      <plugin name='diff_drive_controller' filename='libgazebo_ros_diff_drive.so'>
        <legacyMode>false</legacyMode>
        <alwaysOn>true</alwaysOn>
        <updateRate>1000.0</updateRate>
        <leftJoint>front_left_wheel_joint, rear_left_wheel_joint</leftJoint>
        <rightJoint>front_right_wheel_joint, rear_right_wheel_joint</rightJoint>
        <wheelSeparation>0.5</wheelSeparation>
        <wheelDiameter>0.2</wheelDiameter>
        <wheelTorque>10</wheelTorque>
        <publishTf>1</publishTf>
        <odometryFrame>map</odometryFrame>
        <commandTopic>cmd_vel</commandTopic>
        <odometryTopic>odom</odometryTopic>
        <robotBaseFrame>base_link</robotBaseFrame>
        <wheelAcceleration>2.8</wheelAcceleration>
        <publishWheelJointState>true</publishWheelJointState>
        <publishWheelTF>false</publishWheelTF>
        <odometrySource>world</odometrySource>
        <rosDebugLevel>Debug</rosDebugLevel>
        <robotNamespace>/</robotNamespace>
      </plugin>
      <pose frame=''>0 0 0 0 -0 0</pose>
    </model>
    <model name='nee'>
      <link name='link_0'>
        <pose frame=''>0 0 0 0 -0 0</pose>
        <inertial>
          <mass>1</mass>
          <inertia>
            <ixx>0.166667</ixx>
            <ixy>0</ixy>
            <ixz>0</ixz>
            <iyy>0.166667</iyy>
            <iyz>0</iyz>
            <izz>0.166667</izz>
          </inertia>
        </inertial>
        <visual name='visual'>
          <pose frame=''>0 0 0 0 -0 0</pose>
          <geometry>
            <mesh>
              <uri>/home/sandra/.gazebo/models/meshes/room100.dae</uri>
              <scale>1 1 1</scale>
            </mesh>
          </geometry>
          <material>
            <lighting>1</lighting>
            <script>
              <uri>file://media/materials/scripts/gazebo.material</uri>
              <name>Gazebo/Grey</name>
            </script>
            <ambient>0.3 0.3 0.3 1</ambient>
            <diffuse>0.7 0.7 0.7 1</diffuse>
            <specular>0.01 0.01 0.01 1</specular>
            <emissive>0 0 0 1</emissive>
          </material>
          <cast_shadows>1</cast_shadows>
          <transparency>0</transparency>
        </visual>
        <collision name='collision'>
          <laser_retro>0</laser_retro>
          <max_contacts>10</max_contacts>
          <pose frame=''>0 0 0 0 -0 0</pose>
          <geometry>
            <mesh>
              <uri>/home/sandra/.gazebo/models/meshes/room100.dae</uri>
              <scale>1 1 1</scale>
            </mesh>
          </geometry>
          <surface>
            <friction>
              <ode>
                <mu>1</mu>
                <mu2>1</mu2>
                <fdir1>0 0 0</fdir1>
                <slip1>0</slip1>
                <slip2>0</slip2>
              </ode>
              <torsional>
                <coefficient>1</coefficient>
                <patch_radius>0</patch_radius>
                <surface_radius>0</surface_radius>
                <use_patch_radius>1</use_patch_radius>
                <ode>
                  <slip>0</slip>
                </ode>
              </torsional>
            </friction>
            <bounce>
              <restitution_coefficient>0</restitution_coefficient>
              <threshold>1e+06</threshold>
            </bounce>
            <contact>
              <collide_without_contact>0</collide_without_contact>
              <collide_without_contact_bitmask>1</collide_without_contact_bitmask>
              <collide_bitmask>1</collide_bitmask>
              <ode>
                <soft_cfm>0</soft_cfm>
                <soft_erp>0.2</soft_erp>
                <kp>1e+13</kp>
                <kd>1</kd>
                <max_vel>0.01</max_vel>
                <min_depth>0</min_depth>
              </ode>
              <bullet>
                <split_impulse>1</split_impulse>
                <split_impulse_penetration_threshold>-0.01</split_impulse_penetration_threshold>
                <soft_cfm>0</soft_cfm>
                <soft_erp>0.2</soft_erp>
                <kp>1e+13</kp>
                <kd>1</kd>
              </bullet>
            </contact>
          </surface>
        </collision>
        <self_collide>0</self_collide>
        <kinematic>0</kinematic>
        <gravity>1</gravity>
      </link>
      <static>0</static>
      <allow_auto_disable>1</allow_auto_disable>
      <pose frame=''>0 0 0 0 -0 0</pose>
    </model>
    <model name='ar_marker'>
      <static>1</static>
      <link name='link'>
        <visual name='visual'>
          <geometry>
            <mesh>
              <uri>model://ar_marker/meshes/Marker0.dae</uri>
              <scale>1 1 1</scale>
            </mesh>
          </geometry>
        </visual>
        <self_collide>0</self_collide>
        <kinematic>0</kinematic>
        <gravity>1</gravity>
      </link>
      <pose frame=''>0.193154 11.4466 0 0 -0 0</pose>
    </model>
  </world>
</sdf>
